Workbook

Sheet Variables
A1: URL Stub
A2: https://ivmf.syracuse.edu

Sheet Page Types
A1: Type | B1: Definition
A2: Home
A3: Landing | B3: High-level, journey-focused content. Structurally complex page layout prioritizing dynamic media with visuals and teasers pointing to journey-focused content. Will be the "index" page for the journey/audience segment.
A4: Hub/Directory | B4: Task-focused page within a journey/segement. Strong and simple visual hierarchy for quick determination of destination. One section of prioritized options followed by complete list of options within the journey/segment.
A5: Standard | B5: Most flexible of all page types and mostly a "blank slate" to accommodate a variety of content needs.
A6: Program | B6: Variation of Standard with some specific requirements that apply to only program-related content. Use as subpage of Programs Hub/Directory. This would be used as the "home" for the program, and subpages of the program would use Standard.
A7: Project | B7: Variation of Standard with some specific requirements that apply to only project-related content. Use as subpage of Projects Hub/Directory. This would be used as the "home" for the project, and subpages of the program would use Standard.
A8: Report | B8: Variation of Standard with some specific requirements that apply to only report-related content. Use as subpage of Reports Hub/Directory. This would be used as the "home" for the report, and subpages of the program would use Standard.
A9: Testimonial | B9: Variation of Standard with some specific requirements that apply to only testimonal content. Use as subpage of the Testimonials Hub/Directory.
A10: Index News (Blog) | B10: Specialized blog index focused on article content. Posts selected at feature would be highlighted at top followed by paginated, filterable list of past editions.
A11: Index Articles (Blog) | B11: Specialized blog index focused on article content. Posts selected at feature would be highlighted at top followed by paginated, filterable list of past editions.
A12: Index Newsletter (Blog) | B12: Specialized blog index focused on newsletter content. Feature latest edition at top followed by paginated, filterable list of past editions.
A13: Post (Blog) | B13: Flexible blog post layout with typical blog post features. Use for news, newsletters, and articles. (If specialization is permitted, allow post context to switch between News, Newsletter, or Article to access context-specific features). Allow feature option to bubble item to feature spot(s) on blog indexes.
A14: FAQ | B14: Specialized page with simple and clear content hierarchy, focused on offering question/answer style content categorized under SEO-friendly headings.
A15: Bio | B15: Specialized page related to source list of leadership, staff, and advisory committee

Sheet Drupal
A1: Page Template/Type | B1: Page Title / Nav Label | C1: Notional URL | D1: Section / Path segments | I1: Query
A2: Home | B2: Home | C2: {=_xlfn.LET( _xlpm.path,$D2:$H2, _xlpm.slugPathRange,SUBSTITUTE(LOWER(_xlpm.path)," ","-"), _xlpm.slugPath,_xlfn.TEXTJOIN("/",TRUE,_xlpm.slugPathRange), _xlpm.append,SUBSTITUTE(LOWER($B2)," ","-"), _xlpm.query,SUBSTITUTE(LOWER($I2)," ","-"), _xlpm.duplicate,SUMPRODUCT(--(_xlpm.slugPathRange=_xlpm.append))>0, Variables!$A$2 &IF(_xlpm.slugPath="","","/"&_xlpm.slugPath) &IF(OR(_xlpm.append="",_xlpm.duplicate),"","/"&_xlpm.append) &IF(_xlpm.query="","","?"&_xlpm.query) )} -> https://ivmf.syracuse.edu/home
A3: Landing | B3: About Us | C3: {=_xlfn.LET( _xlpm.path,$D3:$H3, _xlpm.slugPathRange,SUBSTITUTE(LOWER(_xlpm.path)," ","-"), _xlpm.slugPath,_xlfn.TEXTJOIN("/",TRUE,_xlpm.slugPathRange), _xlpm.append,SUBSTITUTE(LOWER($B3)," ","-"), _xlpm.query,SUBSTITUTE(LOWER($I3)," ","-"), _xlpm.duplicate,SUMPRODUCT(--(_xlpm.slugPathRange=_xlpm.append))>0, Variables!$A$2 &IF(_xlpm.slugPath="","","/"&_xlpm.slugPath) &IF(OR(_xlpm.append="",_xlpm.duplicate),"","/"&_xlpm.append) &IF(_xlpm.query="","","?"&_xlpm.query) )} -> https://ivmf.syracuse.edu/about/about-us | D3: About
A4: Standard | B4: Who We Are | C4: {=_xlfn.LET( _xlpm.path,$D4:$H4, _xlpm.slugPathRange,SUBSTITUTE(LOWER(_xlpm.path)," ","-"), _xlpm.slugPath,_xlfn.TEXTJOIN("/",TRUE,_xlpm.slugPathRange), _xlpm.append,SUBSTITUTE(LOWER($B4)," ","-"), _xlpm.query,SUBSTITUTE(LOWER($I4)," ","-"), _xlpm.duplicate,SUMPRODUCT(--(_xlpm.slugPathRange=_xlpm.append))>0, Variables!$A$2 &IF(_xlpm.slugPath="","","/"&_xlpm.slugPath) &IF(OR(_xlpm.append="",_xlpm.duplicate),"","/"&_xlpm.append) &IF(_xlpm.query="","","?"&_xlpm.query) )} -> https://ivmf.syracuse.edu/about/who-we-are | D4: About
A5: Standard | B5: Impact | C5: {=_xlfn.LET( _xlpm.path,$D5:$H5, _xlpm.slugPathRange,SUBSTITUTE(LOWER(_xlpm.path)," ","-"), _xlpm.slugPath,_xlfn.TEXTJOIN("/",TRUE,_xlpm.slugPathRange), _xlpm.append,SUBSTITUTE(LOWER($B5)," ","-"), _xlpm.query,SUBSTITUTE(LOWER($I5)," ","-"), _xlpm.duplicate,SUMPRODUCT(--(_xlpm.slugPathRange=_xlpm.append))>0, Variables!$A$2 &IF(_xlpm.slugPath="","","/"&_xlpm.slugPath) &IF(OR(_xlpm.append="",_xlpm.duplicate),"","/"&_xlpm.append) &IF(_xlpm.query="","","?"&_xlpm.query) )} -> https://ivmf.syracuse.edu/about/impact | D5: About
A6: Standard | B6: Meet the Team | C6: {=_xlfn.LET( _xlpm.path,$D6:$H6, _xlpm.slugPathRange,SUBSTITUTE(LOWER(_xlpm.path)," ","-"), _xlpm.slugPath,_xlfn.TEXTJOIN("/",TRUE,_xlpm.slugPathRange), _xlpm.append,SUBSTITUTE(LOWER($B6)," ","-"), _xlpm.query,SUBSTITUTE(LOWER($I6)," ","-"), _xlpm.duplicate,SUMPRODUCT(--(_xlpm.slugPathRange=_xlpm.append))>0, Variables!$A$2 &IF(_xlpm.slugPath="","","/"&_xlpm.slugPath) &IF(OR(_xlpm.append="",_xlpm.duplicate),"","/"&_xlpm.append) &IF(_xlpm.query="","","?"&_xlpm.query) )} -> https://ivmf.syracuse.edu/about/meet-the-team | D6: About
A7: Standard | B7: Career Education and Training | C7: {=_xlfn.LET( _xlpm.path,$D7:$H7, _xlpm.slugPathRange,SUBSTITUTE(LOWER(_xlpm.path)," ","-"), _xlpm.slugPath,_xlfn.TEXTJOIN("/",TRUE,_xlpm.slugPathRange), _xlpm.append,SUBSTITUTE(LOWER($B7)," ","-"), _xlpm.query,SUBSTITUTE(LOWER($I7)," ","-"), _xlpm.duplicate,SUMPRODUCT(--(_xlpm.slugPathRange=_xlpm.append))>0, Variables!$A$2 &IF(_xlpm.slugPath="","","/"&_xlpm.slugPath) &IF(OR(_xlpm.append="",_xlpm.duplicate),"","/"&_xlpm.append) &IF(_xlpm.query="","","?"&_xlpm.query) )} -> https://ivmf.syracuse.edu/about/career-education-and-training | D7: About
A8: Standard | B8: Partners and Founders | C8: {=_xlfn.LET( _xlpm.path,$D8:$H8, _xlpm.slugPathRange,SUBSTITUTE(LOWER(_xlpm.path)," ","-"), _xlpm.slugPath,_xlfn.TEXTJOIN("/",TRUE,_xlpm.slugPathRange), _xlpm.append,SUBSTITUTE(LOWER($B8)," ","-"), _xlpm.query,SUBSTITUTE(LOWER($I8)," ","-"), _xlpm.duplicate,SUMPRODUCT(--(_xlpm.slugPathRange=_xlpm.append))>0, Variables!$A$2 &IF(_xlpm.slugPath="","","/"&_xlpm.slugPath) &IF(OR(_xlpm.append="",_xlpm.duplicate),"","/"&_xlpm.append) &IF(_xlpm.query="","","?"&_xlpm.query) )} -> https://ivmf.syracuse.edu/about/partners-and-founders | D8: About
A9: Standard | B9: Bunker Labs Legacy | C9: {=_xlfn.LET( _xlpm.path,$D9:$H9, _xlpm.slugPathRange,SUBSTITUTE(LOWER(_xlpm.path)," ","-"), _xlpm.slugPath,_xlfn.TEXTJOIN("/",TRUE,_xlpm.slugPathRange), _xlpm.append,SUBSTITUTE(LOWER($B9)," ","-"), _xlpm.query,SUBSTITUTE(LOWER($I9)," ","-"), _xlpm.duplicate,SUMPRODUCT(--(_xlpm.slugPathRange=_xlpm.append))>0, Variables!$A$2 &IF(_xlpm.slugPath="","","/"&_xlpm.slugPath) &IF(OR(_xlpm.append="",_xlpm.duplicate),"","/"&_xlpm.append) &IF(_xlpm.query="","","?"&_xlpm.query) )} -> https://ivmf.syracuse.edu/about/bunker-labs-legacy | D9: About
A10: Standard | B10: Why SU | C10: {=_xlfn.LET( _xlpm.path,$D10:$H10, _xlpm.slugPathRange,SUBSTITUTE(LOWER(_xlpm.path)," ","-"), _xlpm.slugPath,_xlfn.TEXTJOIN("/",TRUE,_xlpm.slugPathRange), _xlpm.append,SUBSTITUTE(LOWER($B10)," ","-"), _xlpm.query,SUBSTITUTE(LOWER($I10)," ","-"), _xlpm.duplicate,SUMPRODUCT(--(_xlpm.slugPathRange=_xlpm.append))>0, Variables!$A$2 &IF(_xlpm.slugPath="","","/"&_xlpm.slugPath) &IF(OR(_xlpm.append="",_xlpm.duplicate),"","/"&_xlpm.append) &IF(_xlpm.query="","","?"&_xlpm.query) )} -> https://ivmf.syracuse.edu/about/why-su | D10: About
A11: Standard | B11: NVRC | C11: {=_xlfn.LET( _xlpm.path,$D11:$H11, _xlpm.slugPathRange,SUBSTITUTE(LOWER(_xlpm.path)," ","-"), _xlpm.slugPath,_xlfn.TEXTJOIN("/",TRUE,_xlpm.slugPathRange), _xlpm.append,SUBSTITUTE(LOWER($B11)," ","-"), _xlpm.query,SUBSTITUTE(LOWER($I11)," ","-"), _xlpm.duplicate,SUMPRODUCT(--(_xlpm.slugPathRange=_xlpm.append))>0, Variables!$A$2 &IF(_xlpm.slugPath="","","/"&_xlpm.slugPath) &IF(OR(_xlpm.append="",_xlpm.duplicate),"","/"&_xlpm.append) &IF(_xlpm.query="","","?"&_xlpm.query) )} -> https://ivmf.syracuse.edu/about/nvrc | D11: About
A12: Landing | B12: Programs | C12: {=_xlfn.LET( _xlpm.path,$D12:$H12, _xlpm.slugPathRange,SUBSTITUTE(LOWER(_xlpm.path)," ","-"), _xlpm.slugPath,_xlfn.TEXTJOIN("/",TRUE,_xlpm.slugPathRange), _xlpm.append,SUBSTITUTE(LOWER($B12)," ","-"), _xlpm.query,SUBSTITUTE(LOWER($I12)," ","-"), _xlpm.duplicate,SUMPRODUCT(--(_xlpm.slugPathRange=_xlpm.append))>0, Variables!$A$2 &IF(_xlpm.slugPath="","","/"&_xlpm.slugPath) &IF(OR(_xlpm.append="",_xlpm.duplicate),"","/"&_xlpm.append) &IF(_xlpm.query="","","?"&_xlpm.query) )} -> https://ivmf.syracuse.edu/programs | D12: Programs
A13: Program | B13: O2O | C13: {=_xlfn.LET( _xlpm.path,$D13:$H13, _xlpm.slugPathRange,SUBSTITUTE(LOWER(_xlpm.path)," ","-"), _xlpm.slugPath,_xlfn.TEXTJOIN("/",TRUE,_xlpm.slugPathRange), _xlpm.append,SUBSTITUTE(LOWER($B13)," ","-"), _xlpm.query,SUBSTITUTE(LOWER($I13)," ","-"), _xlpm.duplicate,SUMPRODUCT(--(_xlpm.slugPathRange=_xlpm.append))>0, Variables!$A$2 &IF(_xlpm.slugPath="","","/"&_xlpm.slugPath) &IF(OR(_xlpm.append="",_xlpm.duplicate),"","/"&_xlpm.append) &IF(_xlpm.query="","","?"&_xlpm.query) )} -> https://ivmf.syracuse.edu/programs/o2o | D13: Programs | E13: O2O
A14: Standard | B14: Certifications and Learning Pathways | C14: {=_xlfn.LET( _xlpm.path,$D14:$H14, _xlpm.slugPathRange,SUBSTITUTE(LOWER(_xlpm.path)," ","-"), _xlpm.slugPath,_xlfn.TEXTJOIN("/",TRUE,_xlpm.slugPathRange), _xlpm.append,SUBSTITUTE(LOWER($B14)," ","-"), _xlpm.query,SUBSTITUTE(LOWER($I14)," ","-"), _xlpm.duplicate,SUMPRODUCT(--(_xlpm.slugPathRange=_xlpm.append))>0, Variables!$A$2 &IF(_xlpm.slugPath="","","/"&_xlpm.slugPath) &IF(OR(_xlpm.append="",_xlpm.duplicate),"","/"&_xlpm.append) &IF(_xlpm.query="","","?"&_xlpm.query) )} -> https://ivmf.syracuse.edu/programs/o2o/certifications-and-learning-pathways | D14: Programs | E14: O2O
A15: FAQ | B15: FAQ | C15: {=_xlfn.LET( _xlpm.path,$D15:$H15, _xlpm.slugPathRange,SUBSTITUTE(LOWER(_xlpm.path)," ","-"), _xlpm.slugPath,_xlfn.TEXTJOIN("/",TRUE,_xlpm.slugPathRange), _xlpm.append,SUBSTITUTE(LOWER($B15)," ","-"), _xlpm.query,SUBSTITUTE(LOWER($I15)," ","-"), _xlpm.duplicate,SUMPRODUCT(--(_xlpm.slugPathRange=_xlpm.append))>0, Variables!$A$2 &IF(_xlpm.slugPath="","","/"&_xlpm.slugPath) &IF(OR(_xlpm.append="",_xlpm.duplicate),"","/"&_xlpm.append) &IF(_xlpm.query="","","?"&_xlpm.query) )} -> https://ivmf.syracuse.edu/programs/o2o/faq | D15: Programs | E15: O2O
A16: Standard | B16: Employer Partners | C16: {=_xlfn.LET( _xlpm.path,$D16:$H16, _xlpm.slugPathRange,SUBSTITUTE(LOWER(_xlpm.path)," ","-"), _xlpm.slugPath,_xlfn.TEXTJOIN("/",TRUE,_xlpm.slugPathRange), _xlpm.append,SUBSTITUTE(LOWER($B16)," ","-"), _xlpm.query,SUBSTITUTE(LOWER($I16)," ","-"), _xlpm.duplicate,SUMPRODUCT(--(_xlpm.slugPathRange=_xlpm.append))>0, Variables!$A$2 &IF(_xlpm.slugPath="","","/"&_xlpm.slugPath) &IF(OR(_xlpm.append="",_xlpm.duplicate),"","/"&_xlpm.append) &IF(_xlpm.query="","","?"&_xlpm.query) )} -> https://ivmf.syracuse.edu/programs/o2o/employer-partners | D16: Programs | E16: O2O
A17: Standard | B17: Veterans for Public Office | C17: {=_xlfn.LET( _xlpm.path,$D17:$H17, _xlpm.slugPathRange,SUBSTITUTE(LOWER(_xlpm.path)," ","-"), _xlpm.slugPath,_xlfn.TEXTJOIN("/",TRUE,_xlpm.slugPathRange), _xlpm.append,SUBSTITUTE(LOWER($B17)," ","-"), _xlpm.query,SUBSTITUTE(LOWER($I17)," ","-"), _xlpm.duplicate,SUMPRODUCT(--(_xlpm.slugPathRange=_xlpm.append))>0, Variables!$A$2 &IF(_xlpm.slugPath="","","/"&_xlpm.slugPath) &IF(OR(_xlpm.append="",_xlpm.duplicate),"","/"&_xlpm.append) &IF(_xlpm.query="","","?"&_xlpm.query) )} -> https://ivmf.syracuse.edu/programs/vpo/veterans-for-public-office | D17: Programs | E17: VPO
A18: Landing | B18: Entrepreneurship | C18: {=_xlfn.LET( _xlpm.path,$D18:$H18, _xlpm.slugPathRange,SUBSTITUTE(LOWER(_xlpm.path)," ","-"), _xlpm.slugPath,_xlfn.TEXTJOIN("/",TRUE,_xlpm.slugPathRange), _xlpm.append,SUBSTITUTE(LOWER($B18)," ","-"), _xlpm.query,SUBSTITUTE(LOWER($I18)," ","-"), _xlpm.duplicate,SUMPRODUCT(--(_xlpm.slugPathRange=_xlpm.append))>0, Variables!$A$2 &IF(_xlpm.slugPath="","","/"&_xlpm.slugPath) &IF(OR(_xlpm.append="",_xlpm.duplicate),"","/"&_xlpm.append) &IF(_xlpm.query="","","?"&_xlpm.query) )} -> https://ivmf.syracuse.edu/programs/entrepreneurship | D18: Programs | E18: Entrepreneurship
A19: Hub/Directory | B19: Ideation | C19: {=_xlfn.LET( _xlpm.path,$D19:$H19, _xlpm.slugPathRange,SUBSTITUTE(LOWER(_xlpm.path)," ","-"), _xlpm.slugPath,_xlfn.TEXTJOIN("/",TRUE,_xlpm.slugPathRange), _xlpm.append,SUBSTITUTE(LOWER($B19)," ","-"), _xlpm.query,SUBSTITUTE(LOWER($I19)," ","-"), _xlpm.duplicate,SUMPRODUCT(--(_xlpm.slugPathRange=_xlpm.append))>0, Variables!$A$2 &IF(_xlpm.slugPath="","","/"&_xlpm.slugPath) &IF(OR(_xlpm.append="",_xlpm.duplicate),"","/"&_xlpm.append) &IF(_xlpm.query="","","?"&_xlpm.query) )} -> https://ivmf.syracuse.edu/programs/entrepreneurship/ideation | D19: Programs | E19: Entrepreneurship | F19: Ideation
A20: Program | B20: Boots to Business | C20: {=_xlfn.LET( _xlpm.path,$D20:$H20, _xlpm.slugPathRange,SUBSTITUTE(LOWER(_xlpm.path)," ","-"), _xlpm.slugPath,_xlfn.TEXTJOIN("/",TRUE,_xlpm.slugPathRange), _xlpm.append,SUBSTITUTE(LOWER($B20)," ","-"), _xlpm.query,SUBSTITUTE(LOWER($I20)," ","-"), _xlpm.duplicate,SUMPRODUCT(--(_xlpm.slugPathRange=_xlpm.append))>0, Variables!$A$2 &IF(_xlpm.slugPath="","","/"&_xlpm.slugPath) &IF(OR(_xlpm.append="",_xlpm.duplicate),"","/"&_xlpm.append) &IF(_xlpm.query="","","?"&_xlpm.query) )} -> https://ivmf.syracuse.edu/programs/entrepreneurship/ideation/boots-to-business | D20: Programs | E20: Entrepreneurship | F20: Ideation
A21: Program | B21: Strive | C21: {=_xlfn.LET( _xlpm.path,$D21:$H21, _xlpm.slugPathRange,SUBSTITUTE(LOWER(_xlpm.path)," ","-"), _xlpm.slugPath,_xlfn.TEXTJOIN("/",TRUE,_xlpm.slugPathRange), _xlpm.append,SUBSTITUTE(LOWER($B21)," ","-"), _xlpm.query,SUBSTITUTE(LOWER($I21)," ","-"), _xlpm.duplicate,SUMPRODUCT(--(_xlpm.slugPathRange=_xlpm.append))>0, Variables!$A$2 &IF(_xlpm.slugPath="","","/"&_xlpm.slugPath) &IF(OR(_xlpm.append="",_xlpm.duplicate),"","/"&_xlpm.append) &IF(_xlpm.query="","","?"&_xlpm.query) )} -> https://ivmf.syracuse.edu/programs/entrepreneurship/ideation/strive | D21: Programs | E21: Entrepreneurship | F21: Ideation
A22: Program | B22: V-Cap | C22: {=_xlfn.LET( _xlpm.path,$D22:$H22, _xlpm.slugPathRange,SUBSTITUTE(LOWER(_xlpm.path)," ","-"), _xlpm.slugPath,_xlfn.TEXTJOIN("/",TRUE,_xlpm.slugPathRange), _xlpm.append,SUBSTITUTE(LOWER($B22)," ","-"), _xlpm.query,SUBSTITUTE(LOWER($I22)," ","-"), _xlpm.duplicate,SUMPRODUCT(--(_xlpm.slugPathRange=_xlpm.append))>0, Variables!$A$2 &IF(_xlpm.slugPath="","","/"&_xlpm.slugPath) &IF(OR(_xlpm.append="",_xlpm.duplicate),"","/"&_xlpm.append) &IF(_xlpm.query="","","?"&_xlpm.query) )} -> https://ivmf.syracuse.edu/programs/entrepreneurship/ideation/strive/v-cap | D22: Programs | E22: Entrepreneurship | F22: Ideation | G22: Strive
A23: Hub/Directory | B23: Startup | C23: {=_xlfn.LET( _xlpm.path,$D23:$H23, _xlpm.slugPathRange,SUBSTITUTE(LOWER(_xlpm.path)," ","-"), _xlpm.slugPath,_xlfn.TEXTJOIN("/",TRUE,_xlpm.slugPathRange), _xlpm.append,SUBSTITUTE(LOWER($B23)," ","-"), _xlpm.query,SUBSTITUTE(LOWER($I23)," ","-"), _xlpm.duplicate,SUMPRODUCT(--(_xlpm.slugPathRange=_xlpm.append))>0, Variables!$A$2 &IF(_xlpm.slugPath="","","/"&_xlpm.slugPath) &IF(OR(_xlpm.append="",_xlpm.duplicate),"","/"&_xlpm.append) &IF(_xlpm.query="","","?"&_xlpm.query) )} -> https://ivmf.syracuse.edu/programs/entrepreneurship/startup | D23: Programs | E23: Entrepreneurship | F23: Startup
A24: Program | B24: EBV-F-WWP | C24: {=_xlfn.LET( _xlpm.path,$D24:$H24, _xlpm.slugPathRange,SUBSTITUTE(LOWER(_xlpm.path)," ","-"), _xlpm.slugPath,_xlfn.TEXTJOIN("/",TRUE,_xlpm.slugPathRange), _xlpm.append,SUBSTITUTE(LOWER($B24)," ","-"), _xlpm.query,SUBSTITUTE(LOWER($I24)," ","-"), _xlpm.duplicate,SUMPRODUCT(--(_xlpm.slugPathRange=_xlpm.append))>0, Variables!$A$2 &IF(_xlpm.slugPath="","","/"&_xlpm.slugPath) &IF(OR(_xlpm.append="",_xlpm.duplicate),"","/"&_xlpm.append) &IF(_xlpm.query="","","?"&_xlpm.query) )} -> https://ivmf.syracuse.edu/programs/entrepreneurship/startup/ebv-f-wwp | D24: Programs | E24: Entrepreneurship | F24: Startup
A25: Program | B25: Veteran Women Igniting the Spirit of Entrepreneurship | C25: {=_xlfn.LET( _xlpm.path,$D25:$H25, _xlpm.slugPathRange,SUBSTITUTE(LOWER(_xlpm.path)," ","-"), _xlpm.slugPath,_xlfn.TEXTJOIN("/",TRUE,_xlpm.slugPathRange), _xlpm.append,SUBSTITUTE(LOWER($B25)," ","-"), _xlpm.query,SUBSTITUTE(LOWER($I25)," ","-"), _xlpm.duplicate,SUMPRODUCT(--(_xlpm.slugPathRange=_xlpm.append))>0, Variables!$A$2 &IF(_xlpm.slugPath="","","/"&_xlpm.slugPath) &IF(OR(_xlpm.append="",_xlpm.duplicate),"","/"&_xlpm.append) &IF(_xlpm.query="","","?"&_xlpm.query) )} -> https://ivmf.syracuse.edu/programs/entrepreneurship/startup/veteran-women-igniting-the-spirit-of-entrepreneurship | D25: Programs | E25: Entrepreneurship | F25: Startup
A26: Program | B26: Military Founders Lab | C26: {=_xlfn.LET( _xlpm.path,$D26:$H26, _xlpm.slugPathRange,SUBSTITUTE(LOWER(_xlpm.path)," ","-"), _xlpm.slugPath,_xlfn.TEXTJOIN("/",TRUE,_xlpm.slugPathRange), _xlpm.append,SUBSTITUTE(LOWER($B26)," ","-"), _xlpm.query,SUBSTITUTE(LOWER($I26)," ","-"), _xlpm.duplicate,SUMPRODUCT(--(_xlpm.slugPathRange=_xlpm.append))>0, Variables!$A$2 &IF(_xlpm.slugPath="","","/"&_xlpm.slugPath) &IF(OR(_xlpm.append="",_xlpm.duplicate),"","/"&_xlpm.append) &IF(_xlpm.query="","","?"&_xlpm.query) )} -> https://ivmf.syracuse.edu/programs/entrepreneurship/startup/military-founders-lab | D26: Programs | E26: Entrepreneurship | F26: Startup
A27: Program | B27: Growth | C27: {=_xlfn.LET( _xlpm.path,$D27:$H27, _xlpm.slugPathRange,SUBSTITUTE(LOWER(_xlpm.path)," ","-"), _xlpm.slugPath,_xlfn.TEXTJOIN("/",TRUE,_xlpm.slugPathRange), _xlpm.append,SUBSTITUTE(LOWER($B27)," ","-"), _xlpm.query,SUBSTITUTE(LOWER($I27)," ","-"), _xlpm.duplicate,SUMPRODUCT(--(_xlpm.slugPathRange=_xlpm.append))>0, Variables!$A$2 &IF(_xlpm.slugPath="","","/"&_xlpm.slugPath) &IF(OR(_xlpm.append="",_xlpm.duplicate),"","/"&_xlpm.append) &IF(_xlpm.query="","","?"&_xlpm.query) )} -> https://ivmf.syracuse.edu/programs/entrepreneurship/growth | D27: Programs | E27: Entrepreneurship | F27: Growth
A28: Program | B28: Veteran Edge | C28: {=_xlfn.LET( _xlpm.path,$D28:$H28, _xlpm.slugPathRange,SUBSTITUTE(LOWER(_xlpm.path)," ","-"), _xlpm.slugPath,_xlfn.TEXTJOIN("/",TRUE,_xlpm.slugPathRange), _xlpm.append,SUBSTITUTE(LOWER($B28)," ","-"), _xlpm.query,SUBSTITUTE(LOWER($I28)," ","-"), _xlpm.duplicate,SUMPRODUCT(--(_xlpm.slugPathRange=_xlpm.append))>0, Variables!$A$2 &IF(_xlpm.slugPath="","","/"&_xlpm.slugPath) &IF(OR(_xlpm.append="",_xlpm.duplicate),"","/"&_xlpm.append) &IF(_xlpm.query="","","?"&_xlpm.query) )} -> https://ivmf.syracuse.edu/programs/entrepreneurship/growth/veteran-edge | D28: Programs | E28: Entrepreneurship | F28: Growth
A29: Program | B29: Entrepreneurship Bootcamp for Veterans | C29: {=_xlfn.LET( _xlpm.path,$D29:$H29, _xlpm.slugPathRange,SUBSTITUTE(LOWER(_xlpm.path)," ","-"), _xlpm.slugPath,_xlfn.TEXTJOIN("/",TRUE,_xlpm.slugPathRange), _xlpm.append,SUBSTITUTE(LOWER($B29)," ","-"), _xlpm.query,SUBSTITUTE(LOWER($I29)," ","-"), _xlpm.duplicate,SUMPRODUCT(--(_xlpm.slugPathRange=_xlpm.append))>0, Variables!$A$2 &IF(_xlpm.slugPath="","","/"&_xlpm.slugPath) &IF(OR(_xlpm.append="",_xlpm.duplicate),"","/"&_xlpm.append) &IF(_xlpm.query="","","?"&_xlpm.query) )} -> https://ivmf.syracuse.edu/programs/entrepreneurship/growth/entrepreneurship-bootcamp-for-veterans | D29: Programs | E29: Entrepreneurship | F29: Growth
A30: Program | B30: Entrepreneurship Bootcamp for Veterans Accelerate | C30: {=_xlfn.LET( _xlpm.path,$D30:$H30, _xlpm.slugPathRange,SUBSTITUTE(LOWER(_xlpm.path)," ","-"), _xlpm.slugPath,_xlfn.TEXTJOIN("/",TRUE,_xlpm.slugPathRange), _xlpm.append,SUBSTITUTE(LOWER($B30)," ","-"), _xlpm.query,SUBSTITUTE(LOWER($I30)," ","-"), _xlpm.duplicate,SUMPRODUCT(--(_xlpm.slugPathRange=_xlpm.append))>0, Variables!$A$2 &IF(_xlpm.slugPath="","","/"&_xlpm.slugPath) &IF(OR(_xlpm.append="",_xlpm.duplicate),"","/"&_xlpm.append) &IF(_xlpm.query="","","?"&_xlpm.query) )} -> https://ivmf.syracuse.edu/programs/entrepreneurship/growth/entrepreneurship-bootcamp-for-veterans-accelerate | D30: Programs | E30: Entrepreneurship | F30: Growth
A31: Program | B31: Scale | C31: {=_xlfn.LET( _xlpm.path,$D31:$H31, _xlpm.slugPathRange,SUBSTITUTE(LOWER(_xlpm.path)," ","-"), _xlpm.slugPath,_xlfn.TEXTJOIN("/",TRUE,_xlpm.slugPathRange), _xlpm.append,SUBSTITUTE(LOWER($B31)," ","-"), _xlpm.query,SUBSTITUTE(LOWER($I31)," ","-"), _xlpm.duplicate,SUMPRODUCT(--(_xlpm.slugPathRange=_xlpm.append))>0, Variables!$A$2 &IF(_xlpm.slugPath="","","/"&_xlpm.slugPath) &IF(OR(_xlpm.append="",_xlpm.duplicate),"","/"&_xlpm.append) &IF(_xlpm.query="","","?"&_xlpm.query) )} -> https://ivmf.syracuse.edu/programs/entrepreneurship/scale | D31: Programs | E31: Entrepreneurship | F31: Scale
A32: Program | B32: CEOcircle | C32: {=_xlfn.LET( _xlpm.path,$D32:$H32, _xlpm.slugPathRange,SUBSTITUTE(LOWER(_xlpm.path)," ","-"), _xlpm.slugPath,_xlfn.TEXTJOIN("/",TRUE,_xlpm.slugPathRange), _xlpm.append,SUBSTITUTE(LOWER($B32)," ","-"), _xlpm.query,SUBSTITUTE(LOWER($I32)," ","-"), _xlpm.duplicate,SUMPRODUCT(--(_xlpm.slugPathRange=_xlpm.append))>0, Variables!$A$2 &IF(_xlpm.slugPath="","","/"&_xlpm.slugPath) &IF(OR(_xlpm.append="",_xlpm.duplicate),"","/"&_xlpm.append) &IF(_xlpm.query="","","?"&_xlpm.query) )} -> https://ivmf.syracuse.edu/programs/entrepreneurship/scale/ceocircle | D32: Programs | E32: Entrepreneurship | F32: Scale
A33: Landing | B33: All Programs | C33: {=_xlfn.LET( _xlpm.path,$D33:$H33, _xlpm.slugPathRange,SUBSTITUTE(LOWER(_xlpm.path)," ","-"), _xlpm.slugPath,_xlfn.TEXTJOIN("/",TRUE,_xlpm.slugPathRange), _xlpm.append,SUBSTITUTE(LOWER($B33)," ","-"), _xlpm.query,SUBSTITUTE(LOWER($I33)," ","-"), _xlpm.duplicate,SUMPRODUCT(--(_xlpm.slugPathRange=_xlpm.append))>0, Variables!$A$2 &IF(_xlpm.slugPath="","","/"&_xlpm.slugPath) &IF(OR(_xlpm.append="",_xlpm.duplicate),"","/"&_xlpm.append) &IF(_xlpm.query="","","?"&_xlpm.query) )} -> https://ivmf.syracuse.edu/programs/entrepreneurship/all-programs | D33: Programs | E33: Entrepreneurship
A34: Landing | B34: Research Evaluation and CII | C34: {=_xlfn.LET( _xlpm.path,$D34:$H34, _xlpm.slugPathRange,SUBSTITUTE(LOWER(_xlpm.path)," ","-"), _xlpm.slugPath,_xlfn.TEXTJOIN("/",TRUE,_xlpm.slugPathRange), _xlpm.append,SUBSTITUTE(LOWER($B34)," ","-"), _xlpm.query,SUBSTITUTE(LOWER($I34)," ","-"), _xlpm.duplicate,SUMPRODUCT(--(_xlpm.slugPathRange=_xlpm.append))>0, Variables!$A$2 &IF(_xlpm.slugPath="","","/"&_xlpm.slugPath) &IF(OR(_xlpm.append="",_xlpm.duplicate),"","/"&_xlpm.append) &IF(_xlpm.query="","","?"&_xlpm.query) )} -> https://ivmf.syracuse.edu/research-evaluation-and-cii | D34: Research Evaluation and CII
A35: Hub | B35: Evaluation | C35: {=_xlfn.LET( _xlpm.path,$D35:$H35, _xlpm.slugPathRange,SUBSTITUTE(LOWER(_xlpm.path)," ","-"), _xlpm.slugPath,_xlfn.TEXTJOIN("/",TRUE,_xlpm.slugPathRange), _xlpm.append,SUBSTITUTE(LOWER($B35)," ","-"), _xlpm.query,SUBSTITUTE(LOWER($I35)," ","-"), _xlpm.duplicate,SUMPRODUCT(--(_xlpm.slugPathRange=_xlpm.append))>0, Variables!$A$2 &IF(_xlpm.slugPath="","","/"&_xlpm.slugPath) &IF(OR(_xlpm.append="",_xlpm.duplicate),"","/"&_xlpm.append) &IF(_xlpm.query="","","?"&_xlpm.query) )} -> https://ivmf.syracuse.edu/research-evaluation-and-cii/evaluation | D35: Research Evaluation and CII | E35: Evaluation
A36: Hub/Directory | B36: Projects | C36: {=_xlfn.LET( _xlpm.path,$D36:$H36, _xlpm.slugPathRange,SUBSTITUTE(LOWER(_xlpm.path)," ","-"), _xlpm.slugPath,_xlfn.TEXTJOIN("/",TRUE,_xlpm.slugPathRange), _xlpm.append,SUBSTITUTE(LOWER($B36)," ","-"), _xlpm.query,SUBSTITUTE(LOWER($I36)," ","-"), _xlpm.duplicate,SUMPRODUCT(--(_xlpm.slugPathRange=_xlpm.append))>0, Variables!$A$2 &IF(_xlpm.slugPath="","","/"&_xlpm.slugPath) &IF(OR(_xlpm.append="",_xlpm.duplicate),"","/"&_xlpm.append) &IF(_xlpm.query="","","?"&_xlpm.query) )} -> https://ivmf.syracuse.edu/research-evaluation-and-cii/evaluation/projects | D36: Research Evaluation and CII | E36: Evaluation
A37: Project | B37: Project Title | C37: {=_xlfn.LET( _xlpm.path,$D37:$H37, _xlpm.slugPathRange,SUBSTITUTE(LOWER(_xlpm.path)," ","-"), _xlpm.slugPath,_xlfn.TEXTJOIN("/",TRUE,_xlpm.slugPathRange), _xlpm.append,SUBSTITUTE(LOWER($B37)," ","-"), _xlpm.query,SUBSTITUTE(LOWER($I37)," ","-"), _xlpm.duplicate,SUMPRODUCT(--(_xlpm.slugPathRange=_xlpm.append))>0, Variables!$A$2 &IF(_xlpm.slugPath="","","/"&_xlpm.slugPath) &IF(OR(_xlpm.append="",_xlpm.duplicate),"","/"&_xlpm.append) &IF(_xlpm.query="","","?"&_xlpm.query) )} -> https://ivmf.syracuse.edu/research-evaluation-and-cii/projects/project-title | D37: Research Evaluation and CII | E37: Projects
A38: Hub/Directory | B38: Applied Research | C38: {=_xlfn.LET( _xlpm.path,$D38:$H38, _xlpm.slugPathRange,SUBSTITUTE(LOWER(_xlpm.path)," ","-"), _xlpm.slugPath,_xlfn.TEXTJOIN("/",TRUE,_xlpm.slugPathRange), _xlpm.append,SUBSTITUTE(LOWER($B38)," ","-"), _xlpm.query,SUBSTITUTE(LOWER($I38)," ","-"), _xlpm.duplicate,SUMPRODUCT(--(_xlpm.slugPathRange=_xlpm.append))>0, Variables!$A$2 &IF(_xlpm.slugPath="","","/"&_xlpm.slugPath) &IF(OR(_xlpm.append="",_xlpm.duplicate),"","/"&_xlpm.append) &IF(_xlpm.query="","","?"&_xlpm.query) )} -> https://ivmf.syracuse.edu/research-evaluation-and-cii/research/applied-research | D38: Research Evaluation and CII | E38: Research
A39: Project | B39: Projects | C39: {=_xlfn.LET( _xlpm.path,$D39:$H39, _xlpm.slugPathRange,SUBSTITUTE(LOWER(_xlpm.path)," ","-"), _xlpm.slugPath,_xlfn.TEXTJOIN("/",TRUE,_xlpm.slugPathRange), _xlpm.append,SUBSTITUTE(LOWER($B39)," ","-"), _xlpm.query,SUBSTITUTE(LOWER($I39)," ","-"), _xlpm.duplicate,SUMPRODUCT(--(_xlpm.slugPathRange=_xlpm.append))>0, Variables!$A$2 &IF(_xlpm.slugPath="","","/"&_xlpm.slugPath) &IF(OR(_xlpm.append="",_xlpm.duplicate),"","/"&_xlpm.append) &IF(_xlpm.query="","","?"&_xlpm.query) )} -> https://ivmf.syracuse.edu/research-evaluation-and-cii/projects | D39: Research Evaluation and CII | E39: Projects
A40: Report | B40: Employement Report | C40: {=_xlfn.LET( _xlpm.path,$D40:$H40, _xlpm.slugPathRange,SUBSTITUTE(LOWER(_xlpm.path)," ","-"), _xlpm.slugPath,_xlfn.TEXTJOIN("/",TRUE,_xlpm.slugPathRange), _xlpm.append,SUBSTITUTE(LOWER($B40)," ","-"), _xlpm.query,SUBSTITUTE(LOWER($I40)," ","-"), _xlpm.duplicate,SUMPRODUCT(--(_xlpm.slugPathRange=_xlpm.append))>0, Variables!$A$2 &IF(_xlpm.slugPath="","","/"&_xlpm.slugPath) &IF(OR(_xlpm.append="",_xlpm.duplicate),"","/"&_xlpm.append) &IF(_xlpm.query="","","?"&_xlpm.query) )} -> https://ivmf.syracuse.edu/research-evaluation-and-cii/projects/employement-report | D40: Research Evaluation and CII | E40: Projects
...

Sheet WordPress
A1: Page Title | B1: URL | C1: Section
A2: About IVMF | B2: https://ivmf.syracuse.edu/about-ivmf/ | C2: About
A3: Team | B3: https://ivmf.syracuse.edu/about-ivmf/team/ | C3: About
A4: History | B4: https://ivmf.syracuse.edu/about-ivmf/history-timeline/ | C4: About
A5: BL History | B5: https://ivmf.syracuse.edu/bunker-labs-a-legacy-of-impact/ | C5: About
A6: Impact | B6: https://ivmf.syracuse.edu/about-ivmf/impact/ | C6: About
A7: Careers | B7: Forward | C7: About
A8: NVRC | B8: forward | C8: About
A9: Why SU | B9: https://ivmf.syracuse.edu/about-ivmf/connection-with-su/ | C9: About
A10: Partners & Funders | B10: https://ivmf.syracuse.edu/about-ivmf/partners-funders/ | C10: About
A11: Programs | B11: https://ivmf.syracuse.edu/programs/ | C11: Top Level
A12: Our Programs | B12: https://ivmf.syracuse.edu/our-programs/ | C12: Top Level
... A71: Google Cyber | B71: https://ivmf.syracuse.edu/google-ai-essentials/ | C71: Career Training
A72: Google AI | C72: Career Training
A73: VPPCE | B73: https://ivmf.syracuse.edu/veterans-program-for-politics-and-civic-engagement/ | C73: Career Training
A74: Community Services | B74: https://ivmf.syracuse.edu/programs/community-services/ | C74: Community Services
A75: AmericaServes | B75: https://ivmf.syracuse.edu/programs/community-services/americaserves/ | C75: Community Services
A76: AmericaServes Location | B76: https://ivmf.syracuse.edu/programs/community-services/americaserves/locations/ | C76: Community Services
A77: AmericaServes Insights | B77: https://ivmf.syracuse.edu/programs/community-services/americaserves/insights/ | C77: Community Services
A78: AmericaServes Technical Assistance | B78: https://ivmf.syracuse.edu/programs/community-services/technical-assistance/ | C78: Community Services
A79: AS Location - Serving Together | B79: Forward | C79: Community Services
A80: AS location - NC Serves | B80: Forward | C80: Community Services
A81: AS Location - NYC | B81: Forward | C81: Community Services
A82: AS Location - Update | B82: Forward | C82: Community Services
A83: AS Location - PAServes | B83: https://ivmf.syracuse.edu/programs/community-services/americaserves/locations/paserves/ | C83: Community Services
A84: AS Location - RIServes | B84: Forward | C84: Community Services
... A154: Life After Service | B154: https://ivmf.syracuse.edu/life-after-service/ | C154: Comcast Ad Landing Page

Sheet Redirect Map
A1: Wordpress Page | B1: Wordpress URL | C1: Drupal Page | D1: Drupal URL | E1: Notes
A2: =IF(WordPress!A2="","",WordPress!A2) -> About IVMF | B2: {=IF($A2="","",_xlfn.XLOOKUP(TRIM($A2),TRIM(WordPress!$A$2:$A$1000),WordPress!$B$2:$B$1000,""))} -> https://ivmf.syracuse.edu/about-ivmf/ | D2: {=IF($C2="","",_xlfn.XLOOKUP(TRIM($C2),TRIM(Drupal!$B$2:$B$75),Drupal!$C$2:$C$75,""))}
A3: =IF(WordPress!A3="","",WordPress!A3) -> Team | B3: {=IF($A3="","",_xlfn.XLOOKUP(TRIM($A3),TRIM(WordPress!$A$2:$A$1000),WordPress!$B$2:$B$1000,""))} -> https://ivmf.syracuse.edu/about-ivmf/team/ | D3: {=IF($C3="","",_xlfn.XLOOKUP(TRIM($C3),TRIM(Drupal!$B$2:$B$75),Drupal!$C$2:$C$75,""))}
A4: =IF(WordPress!A4="","",WordPress!A4) -> History | B4: {=IF($A4="","",_xlfn.XLOOKUP(TRIM($A4),TRIM(WordPress!$A$2:$A$1000),WordPress!$B$2:$B$1000,""))} -> https://ivmf.syracuse.edu/about-ivmf/history-timeline/ | D4: {=IF($C4="","",_xlfn.XLOOKUP(TRIM($C4),TRIM(Drupal!$B$2:$B$75),Drupal!$C$2:$C$75,""))}
A5: =IF(WordPress!A5="","",WordPress!A5) -> BL History | B5: {=IF($A5="","",_xlfn.XLOOKUP(TRIM($A5),TRIM(WordPress!$A$2:$A$1000),WordPress!$B$2:$B$1000,""))} -> https://ivmf.syracuse.edu/bunker-labs-a-legacy-of-impact/ | D5: {=IF($C5="","",_xlfn.XLOOKUP(TRIM($C5),TRIM(Drupal!$B$2:$B$75),Drupal!$C$2:$C$75,""))}
A6: =IF(WordPress!A6="","",WordPress!A6) -> Impact | B6: {=IF($A6="","",_xlfn.XLOOKUP(TRIM($A6),TRIM(WordPress!$A$2:$A$1000),WordPress!$B$2:$B$1000,""))} -> https://ivmf.syracuse.edu/about-ivmf/impact/ | D6: {=IF($C6="","",_xlfn.XLOOKUP(TRIM($C6),TRIM(Drupal!$B$2:$B$75),Drupal!$C$2:$C$75,""))}
A7: =IF(WordPress!A12="","",WordPress!A12) -> Our Programs | B7: {=IF($A7="","",_xlfn.XLOOKUP(TRIM($A7),TRIM(WordPress!$A$2:$A$1000),WordPress!$B$2:$B$1000,""))} -> https://ivmf.syracuse.edu/our-programs/ | D7: {=IF($C7="","",_xlfn.XLOOKUP(TRIM($C7),TRIM(Drupal!$B$2:$B$75),Drupal!$C$2:$C$75,""))}
A8: =IF(WordPress!A13="","",WordPress!A13) -> Entreprenuership | B8: {=IF($A8="","",_xlfn.XLOOKUP(TRIM($A8),TRIM(WordPress!$A$2:$A$1000),WordPress!$B$2:$B$1000,""))} -> https://ivmf.syracuse.edu/programs/entrepreneurship/ | D8: {=IF($C8="","",_xlfn.XLOOKUP(TRIM($C8),TRIM(Drupal!$B$2:$B$75),Drupal!$C$2:$C$75,""))}
A9: =IF(WordPress!A14="","",WordPress!A14) -> Getting Started | B9: {=IF($A9="","",_xlfn.XLOOKUP(TRIM($A9),TRIM(WordPress!$A$2:$A$1000),WordPress!$B$2:$B$1000,""))} -> https://ivmf.syracuse.edu/programs/entrepreneurship/getting-started/ | D9: {=IF($C9="","",_xlfn.XLOOKUP(TRIM($C9),TRIM(Drupal!$B$2:$B$75),Drupal!$C$2:$C$75,""))}
A10: =IF(WordPress!A15="","",WordPress!A15) -> Ideation | B10: {=IF($A10="","",_xlfn.XLOOKUP(TRIM($A10),TRIM(WordPress!$A$2:$A$1000),WordPress!$B$2:$B$1000,""))} -> https://ivmf.syracuse.edu/programs/entrepreneurship/ideation/ | D10: {=IF($C10="","",_xlfn.XLOOKUP(TRIM($C10),TRIM(Drupal!$B$2:$B$75),Drupal!$C$2:$C$75,""))}
A11: =IF(WordPress!A16="","",WordPress!A16) -> Boots to Business | B11: {=IF($A11="","",_xlfn.XLOOKUP(TRIM($A11),TRIM(WordPress!$A$2:$A$1000),WordPress!$B$2:$B$1000,""))} -> https://ivmf.syracuse.edu/programs/entrepreneurship/ideation/boots-to-business/ | D11: {=IF($C11="","",_xlfn.XLOOKUP(TRIM($C11),TRIM(Drupal!$B$2:$B$75),Drupal!$C$2:$C$75,""))}
A12: =IF(WordPress!A17="","",WordPress!A17) -> STRIVE | B12: {=IF($A12="","",_xlfn.XLOOKUP(TRIM($A12),TRIM(WordPress!$A$2:$A$1000),WordPress!$B$2:$B$1000,""))} -> https://ivmf.syracuse.edu/programs/entrepreneurship/ideation/strive/ | D12: {=IF($C12="","",_xlfn.XLOOKUP(TRIM($C12),TRIM(Drupal!$B$2:$B$75),Drupal!$C$2:$C$75,""))}
A13: =IF(WordPress!A18="","",WordPress!A18) -> Start Up | B13: {=IF($A13="","",_xlfn.XLOOKUP(TRIM($A13),TRIM(WordPress!$A$2:$A$1000),WordPress!$B$2:$B$1000,""))} -> https://ivmf.syracuse.edu/programs/entrepreneurship/start-up/ | D13: {=IF($C13="","",_xlfn.XLOOKUP(TRIM($C13),TRIM(Drupal!$B$2:$B$75),Drupal!$C$2:$C$75,""))}
A14: =IF(WordPress!A19="","",WordPress!A19) -> V-WISE | B14: {=IF($A14="","",_xlfn.XLOOKUP(TRIM($A14),TRIM(WordPress!$A$2:$A$1000),WordPress!$B$2:$B$1000,""))} -> https://ivmf.syracuse.edu/programs/entrepreneurship/start-up/v-wise/ | D14: {=IF($C14="","",_xlfn.XLOOKUP(TRIM($C14),TRIM(Drupal!$B$2:$B$75),Drupal!$C$2:$C$75,""))}
A15: =IF(WordPress!A20="","",WordPress!A20) -> V-WISE APP | B15: {=IF($A15="","",_xlfn.XLOOKUP(TRIM($A15),TRIM(WordPress!$A$2:$A$1000),WordPress!$B$2:$B$1000,""))} -> https://ivmf.syracuse.edu/programs/entrepreneurship/start-up/v-wise/v-wise-application/ | D15: {=IF($C15="","",_xlfn.XLOOKUP(TRIM($C15),TRIM(Drupal!$B$2:$B$75),Drupal!$C$2:$C$75,""))}
A16: =IF(WordPress!A21="","",WordPress!A21) -> V-WISE TY | B16: {=IF($A16="","",_xlfn.XLOOKUP(TRIM($A16),TRIM(WordPress!$A$2:$A$1000),WordPress!$B$2:$B$1000,""))} -> https://ivmf.syracuse.edu/programs/entrepreneurship/start-up/v-wise/v-wise-application/thank-you/ | D16: {=IF($C16="","",_xlfn.XLOOKUP(TRIM($C16),TRIM(Drupal!$B$2:$B$75),Drupal!$C$2:$C$75,""))}
A17: =IF(WordPress!A22="","",WordPress!A22) -> EBV | B17: {=IF($A17="","",_xlfn.XLOOKUP(TRIM($A17),TRIM(WordPress!$A$2:$A$1000),WordPress!$B$2:$B$1000,""))} -> https://ivmf.syracuse.edu/programs/entrepreneurship/start-up/ebv/ | D17: {=IF($C17="","",_xlfn.XLOOKUP(TRIM($C17),TRIM(Drupal!$B$2:$B$75),Drupal!$C$2:$C$75,""))}
A18: =IF(WordPress!A23="","",WordPress!A23) -> EBV - APP | B18: {=IF($A18="","",_xlfn.XLOOKUP(TRIM($A18),TRIM(WordPress!$A$2:$A$1000),WordPress!$B$2:$B$1000,""))} -> https://ivmf.syracuse.edu/programs/entrepreneurship/start-up/ebv/ebv-application/ | D18: {=IF($C18="","",_xlfn.XLOOKUP(TRIM($C18),TRIM(Drupal!$B$2:$B$75),Drupal!$C$2:$C$75,""))}
... A114: =IF(WordPress!A119="","",WordPress!A119) -> Research Opportunities | B114: {=IF($A114="","",_xlfn.XLOOKUP(TRIM($A114),TRIM(WordPress!$A$2:$A$1000),WordPress!$B$2:$B$1000,""))} -> https://ivmf.syracuse.edu/rostker-ivmf-dissertation-research-fund/ | D114: {=IF($C114="","",_xlfn.XLOOKUP(TRIM($C114),TRIM(Drupal!$B$2:$B$75),Drupal!$C$2:$C$75,""))}
A115: =IF(WordPress!A120="","",WordPress!A120) -> Evaluation & Analytics | B115: {=IF($A115="","",_xlfn.XLOOKUP(TRIM($A115),TRIM(WordPress!$A$2:$A$1000),WordPress!$B$2:$B$1000,""))} -> https://ivmf.syracuse.edu/research-analytics/evaluation-analytics/ | C115: Dashboards | D115: {=IF($C115="","",_xlfn.XLOOKUP(TRIM($C115),TRIM(Drupal!$B$2:$B$75),Drupal!$C$2:$C$75,""))} -> https://ivmf.syracuse.edu/research-evaluation-and-cii/dashboards
A116: =IF(WordPress!A121="","",WordPress!A121) -> Current Projects | B116: {=IF($A116="","",_xlfn.XLOOKUP(TRIM($A116),TRIM(WordPress!$A$2:$A$1000),WordPress!$B$2:$B$1000,""))} -> https://ivmf.syracuse.edu/research-analytics/evaluation-analytics/current-projects/ | C116: Projects | D116: {=IF($C116="","",_xlfn.XLOOKUP(TRIM($C116),TRIM(Drupal!$B$2:$B$75),Drupal!$C$2:$C$75,""))} -> https://ivmf.syracuse.edu/research-evaluation-and-cii/evaluation/projects
A117: =IF(WordPress!A122="","",WordPress!A122) -> Past Projects | B117: {=IF($A117="","",_xlfn.XLOOKUP(TRIM($A117),TRIM(WordPress!$A$2:$A$1000),WordPress!$B$2:$B$1000,""))} -> https://ivmf.syracuse.edu/research-analytics/evaluation-analytics/past-projects/ | C117: Projects | D117: {=IF($C117="","",_xlfn.XLOOKUP(TRIM($C117),TRIM(Drupal!$B$2:$B$75),Drupal!$C$2:$C$75,""))} -> https://ivmf.syracuse.edu/research-evaluation-and-cii/evaluation/projects
A118: =IF(WordPress!A123="","",WordPress!A123) -> Projects | B118: {=IF($A118="","",_xlfn.XLOOKUP(TRIM($A118),TRIM(WordPress!$A$2:$A$1000),WordPress!$B$2:$B$1000,""))} -> https://ivmf.syracuse.edu/research-analytics/evaluation-analytics/projects/ | C118: Projects | D118: {=IF($C118="","",_xlfn.XLOOKUP(TRIM($C118),TRIM(Drupal!$B$2:$B$75),Drupal!$C$2:$C$75,""))} -> https://ivmf.syracuse.edu/research-evaluation-and-cii/evaluation/projects
A119: =IF(WordPress!A124="","",WordPress!A124) -> Service Offerings | B119: {=IF($A119="","",_xlfn.XLOOKUP(TRIM($A119),TRIM(WordPress!$A$2:$A$1000),WordPress!$B$2:$B$1000,""))} -> https://ivmf.syracuse.edu/research-analytics/evaluation-analytics/service-offerings/ | D119: {=IF($C119="","",_xlfn.XLOOKUP(TRIM($C119),TRIM(Drupal!$B$2:$B$75),Drupal!$C$2:$C$75,""))}
A120: =IF(WordPress!A125="","",WordPress!A125) -> Policy Engagement | B120: {=IF($A120="","",_xlfn.XLOOKUP(TRIM($A120),TRIM(WordPress!$A$2:$A$1000),WordPress!$B$2:$B$1000,""))} -> https://ivmf.syracuse.edu/research-analytics/policy-engagement/ | D120: {=IF($C120="","",_xlfn.XLOOKUP(TRIM($C120),TRIM(Drupal!$B$2:$B$75),Drupal!$C$2:$C$75,""))}
A121: =IF(WordPress!A126="","",WordPress!A126) -> Policy Priorities | B121: {=IF($A121="","",_xlfn.XLOOKUP(TRIM($A121),TRIM(WordPress!$A$2:$A$1000),WordPress!$B$2:$B$1000,""))} -> https://ivmf.syracuse.edu/ivmf-policy-priorities/ | D121: {=IF($C121="","",_xlfn.XLOOKUP(TRIM($C121),TRIM(Drupal!$B$2:$B$75),Drupal!$C$2:$C$75,""))}
A122: =IF(WordPress!A127="","",WordPress!A127) -> Data Insights and Tools | B122: {=IF($A122="","",_xlfn.XLOOKUP(TRIM($A122),TRIM(WordPress!$A$2:$A$1000),WordPress!$B$2:$B$1000,""))} -> https://ivmf.syracuse.edu/research-analytics/data-insights-tools/ | D122: {=IF($C122="","",_xlfn.XLOOKUP(TRIM($C122),TRIM(Drupal!$B$2:$B$75),Drupal!$C$2:$C$75,""))}
A123: =IF(WordPress!A128="","",WordPress!A128) -> Data Philosophy | B123: {=IF($A123="","",_xlfn.XLOOKUP(TRIM($A123),TRIM(WordPress!$A$2:$A$1000),WordPress!$B$2:$B$1000,""))} -> https://ivmf.syracuse.edu/research-analytics/veteran-data-insights/data-philosophy/ | D123: {=IF($C123="","",_xlfn.XLOOKUP(TRIM($C123),TRIM(Drupal!$B$2:$B$75),Drupal!$C$2:$C$75,""))}
A124: =IF(WordPress!A129="","",WordPress!A129) -> Data Strategy | B124: {=IF($A124="","",_xlfn.XLOOKUP(TRIM($A124),TRIM(WordPress!$A$2:$A$1000),WordPress!$B$2:$B$1000,""))} -> https://ivmf.syracuse.edu/research-analytics/veteran-data-insights/data-strategy/ | D124: {=IF($C124="","",_xlfn.XLOOKUP(TRIM($C124),TRIM(Drupal!$B$2:$B$75),Drupal!$C$2:$C$75,""))}
A125: =IF(WordPress!A130="","",WordPress!A130) -> VSTART | B125: {=IF($A125="","",_xlfn.XLOOKUP(TRIM($A125),TRIM(WordPress!$A$2:$A$1000),WordPress!$B$2:$B$1000,""))} -> https://ivmf.syracuse.edu/research-analytics/veteran-data-insights/v-start/ | C125: V-Start | D125: {=IF($C125="","",_xlfn.XLOOKUP(TRIM($C125),TRIM(Drupal!$B$2:$B$75),Drupal!$C$2:$C$75,""))} -> https://ivmf.syracuse.edu/research-evaluation-and-cii/dashboards/v-start
A126: =IF(WordPress!A131="","",WordPress!A131) -> VSTART Dashboard | B126: {=IF($A126="","",_xlfn.XLOOKUP(TRIM($A126),TRIM(WordPress!$A$2:$A$1000),WordPress!$B$2:$B$1000,""))} -> https://ivmf.syracuse.edu/research-analytics/veteran-data-insights/v-start/v-start-dashboards/ | C126: V-Start | D126: {=IF($C126="","",_xlfn.XLOOKUP(TRIM($C126),TRIM(Drupal!$B$2:$B$75),Drupal!$C$2:$C$75,""))} -> https://ivmf.syracuse.edu/research-evaluation-and-cii/dashboards/v-start
A127: =IF(WordPress!A132="","",WordPress!A132) -> NSMAE Dashboard | B127: {=IF($A127="","",_xlfn.XLOOKUP(TRIM($A127),TRIM(WordPress!$A$2:$A$1000),WordPress!$B$2:$B$1000,""))} -> https://ivmf.syracuse.edu/research-analytics/data-insights-tools/nsmae-dashboard/ | D127: {=IF($C127="","",_xlfn.XLOOKUP(TRIM($C127),TRIM(Drupal!$B$2:$B$75),Drupal!$C$2:$C$75,""))}
A128: =IF(WordPress!A133="","",WordPress!A133) -> Support IVMF | B128: {=IF($A128="","",_xlfn.XLOOKUP(TRIM($A128),TRIM(WordPress!$A$2:$A$1000),WordPress!$B$2:$B$1000,""))} -> https://ivmf.syracuse.edu/support-ivmf/ | D128: {=IF($C128="","",_xlfn.XLOOKUP(TRIM($C128),TRIM(Drupal!$B$2:$B$75),Drupal!$C$2:$C$75,""))}
A129: =IF(WordPress!A134="","",WordPress!A134) -> Alumni | B129: {=IF($A129="","",_xlfn.XLOOKUP(TRIM($A129),TRIM(WordPress!$A$2:$A$1000),WordPress!$B$2:$B$1000,""))} -> https://ivmf.syracuse.edu/alumni | D129: {=IF($C129="","",_xlfn.XLOOKUP(TRIM($C129),TRIM(Drupal!$B$2:$B$75),Drupal!$C$2:$C$75,""))}
A130: =IF(WordPress!A135="","",WordPress!A135) -> Alumni - O2O | B130: {=IF($A130="","",_xlfn.XLOOKUP(TRIM($A130),TRIM(WordPress!$A$2:$A$1000),WordPress!$B$2:$B$1000,""))} -> https://ivmf.syracuse.edu/alumni/o2o-pps/ | D130: {=IF($C130="","",_xlfn.XLOOKUP(TRIM($C130),TRIM(Drupal!$B$2:$B$75),Drupal!$C$2:$C$75,""))}
A131: =IF(WordPress!A136="","",WordPress!A136) -> Alumni - EBV | B131: {=IF($A131="","",_xlfn.XLOOKUP(TRIM($A131),TRIM(WordPress!$A$2:$A$1000),WordPress!$B$2:$B$1000,""))} -> https://ivmf.syracuse.edu/alumni/ebv-pps/ | D131: {=IF($C131="","",_xlfn.XLOOKUP(TRIM($C131),TRIM(Drupal!$B$2:$B$75),Drupal!$C$2:$C$75,""))}
A132: =IF(WordPress!A137="","",WordPress!A137) -> Alumni - BL | B132: {=IF($A132="","",_xlfn.XLOOKUP(TRIM($A132),TRIM(WordPress!$A$2:$A$1000),WordPress!$B$2:$B$1000,""))} -> https://ivmf.syracuse.edu/alumni/bl-pps | D132: {=IF($C132="","",_xlfn.XLOOKUP(TRIM($C132),TRIM(Drupal!$B$2:$B$75),Drupal!$C$2:$C$75,""))}
A133: =IF(WordPress!A138="","",WordPress!A138) -> Alumni - VWISE | B133: {=IF($A133="","",_xlfn.XLOOKUP(TRIM($A133),TRIM(WordPress!$A$2:$A$1000),WordPress!$B$2:$B$1000,""))} -> https://ivmf.syracuse.edu/alumni/v-vwise-pps | D133: {=IF($C133="","",_xlfn.XLOOKUP(TRIM($C133),TRIM(Drupal!$B$2:$B$75),Drupal!$C$2:$C$75,""))}
A134: =IF(WordPress!A139="","",WordPress!A139) -> Alumni - Volunteer | B134: {=IF($A134="","",_xlfn.XLOOKUP(TRIM($A134),TRIM(WordPress!$A$2:$A$1000),WordPress!$B$2:$B$1000,""))} -> https://ivmf.syracuse.edu/alumni/volunteer-form | D134: {=IF($C134="","",_xlfn.XLOOKUP(TRIM($C134),TRIM(Drupal!$B$2:$B$75),Drupal!$C$2:$C$75,""))}
A135: =IF(WordPress!A140="","",WordPress!A140) -> Shopping Guide | B135: {=IF($A135="","",_xlfn.XLOOKUP(TRIM($A135),TRIM(WordPress!$A$2:$A$1000),WordPress!$B$2:$B$1000,""))} -> https://ivmf.syracuse.edu/buy-military-owned/ | D135: {=IF($C135="","",_xlfn.XLOOKUP(TRIM($C135),TRIM(Drupal!$B$2:$B$75),Drupal!$C$2:$C$75,""))}
...
